Workbook

Sheet 770
A1: Classic
B2: RMSE | C2: MAPE | D2: PCC | E2: Epoch | F2: Quantum_RMSE | G2: Quantum_MAPE | H2: Quantum_PCC | I2: Quantum_Epoch | J2: Baseline | K2: Stacked_RMSE | L2: Stacked_MAPE | M2: Stacked_PCC | U2: 770 LSTM vs QLSTM | V2: 770 LSTM vs Stacked QLSTM | W2: 1440 LSTM vs QLSTM | X2: 1440 LSTM vs Stacked QLSTM
A3: Fold 1 | B3: 2216.79 | C3: 18.76 | D3: 0.307 | E3: 7 | F3: 2330.79 | G3: 16.7 | H3: 0.527 | I3: 7 | J3: 17.65 | K3: 1847.41 | L3: 12.09 | M3: 0.646 | T3: RMSE | U3: =_xlfn.T.TEST(B3:B10,F3:F10,1,1) -> 0.18335092 | V3: =_xlfn.T.TEST(B3:B10,K3:K10,1,1) -> 0.0018714307 | W3: =_xlfn.T.TEST(Both!B2:B9,Both!F2:F9,1,1) -> 0.099219287 | X3: =_xlfn.T.TEST(Both!C2:C9,Both!K2:K9,1,1) -> 2.0944258e-10
A4: Fold 2 | B4: 2562.1 | C4: 20.08 | D4: 0.425 | E4: 7 | F4: 2303.72 | G4: 22.95 | H4: 0.454 | I4: 6 | J4: 17.12 | K4: 1961.48 | L4: 12.81 | M4: 0.586 | T4: MAPE | U4: =_xlfn.T.TEST(C3:C10,G3:G10,1,1) -> 0.11897886 | V4: =_xlfn.T.TEST(C3:C10,L3:L10,1,1) -> 0.0007009536 | W4: =_xlfn.T.TEST(Both!C2:C9,Both!G2:G9,1,1) -> 0.085016221 | X4: =_xlfn.T.TEST(Both!C2:C9,Both!L2:L9,1,1) -> 0.010668403
A5: Fold 3 | B5: 1909.64 | C5: 12.79 | D5: 0.636 | E5: 7 | F5: 2059.33 | G5: 15.74 | H5: 0.507 | I5: 6 | J5: 16.81 | K5: 1723.38 | L5: 10.89 | M5: 0.564 | T5: PCC | U5: =_xlfn.T.TEST(D3:D10,H3:H10,1,1) -> 0.46270365 | V5: =_xlfn.T.TEST(D3:D10,M3:M10,1,1) -> 0.080361598 | W5: =_xlfn.T.TEST(Both!D2:D9,Both!H2:H9,1,1) -> 0.16587381 | X5: =_xlfn.T.TEST(Both!D2:D9,Both!M2:M9,1,1) -> 0.20783006
A6: Fold 4 | B6: 2174.97 | C6: 18.77 | D6: 0.548 | E6: 7 | F6: 2544.95 | G6: 18.74 | H6: 0.449 | I6: 12 | K6: 1723.38 | L6: 10.89 | M6: 0.564
A7: Fold 5 | B7: 2148.86 | C7: 16.86 | D7: 0.4 | E7: 7 | F7: 2400.58 | G7: 19.58 | H7: 0.377 | I7: 6 | K7: 2100.61 | L7: 13.78 | M7: 0.411
A8: Fold 6 | B8: 2192.78 | C8: 14.06 | D8: 0.524 | E8: 25 | F8: 2681.14 | G8: 26.75 | H8: 0.367 | I8: 6 | K8: 2086.59 | L8: 13.42 | M8: 0.4
A9: Fold 7 | B9: 2486.08 | C9: 19.54 | D9: 0.21 | E9: 7 | F9: 2369.4 | G9: 15.96 | H9: 0.324 | I9: 6 | J9: 0.1494 | K9: 1873.11 | L9: 11.63 | M9: 0.478
A10: Fold 8 | B10: 2532.29 | C10: 17.48 | D10: 0.23 | E10: 8 | F10: 2291.95 | G10: 19.79 | H10: 0.24 | I10: 6 | J10: 12.59 | K10: 1772.85 | L10: 11.23 | M10: 0.349
A11: Average | B11: =GEOMEAN(B3:B10) -> 2267.8778 | C11: =GEOMEAN(C3:C10) -> 17.103305 | D11: =GEOMEAN(D3:D10) -> 0.38272596 | E11: =GEOMEAN(E3:E10) -> 8.3454984 | F11: =GEOMEAN(F3:F10) -> 2366.4763 | G11: =GEOMEAN(G3:G10) -> 19.230301 | H11: =GEOMEAN(H3:H10) -> 0.39444418 | I11: =GEOMEAN(I3:I10) -> 6.6703458 | ... M11: =GEOMEAN(M3:M10) -> 0.48961581
A12: delta | B12: =B11-F11 -> -98.598521 | C12: =C11-G11 -> -2.1269963 | D12: =D11-H11 -> -0.01171822 | E12: =E11-I11 -> 1.6751526
A13: Standard deviation | B13: =STDEV(B3:B10) -> 227.61622 | C13: =STDEV(C3:C10) -> 2.6213887 | D13: =STDEV(D3:D10) -> 0.15420302 | E13: =STDEV(E3:E10) -> 6.3231434 | F13: =STDEV(F3:F10) -> 183.9369 | G13: =STDEV(G3:G10) -> 3.7727744 | H13: =STDEV(H3:H10) -> 0.096832606 | I13: =STDEV(I3:I10) -> 2.1001701 | ... M13: =STDEV(M3:M10) -> 0.1056338
A14: RMSE different | B14: =STDEV(B4:B11) -> 226.36879
A15: MAPE | B15: =STDEV(B5:B12) -> 851.46506
A16: PPC different | B16: =STDEV(B6:B13) -> 1048.2721
A17: Epoch | B17: =STDEV(B7:B14) -> 1154.1945
A96: - DailyPrecipitation | C96: - DailyPrecipitation | F96: - DailyPrecipitation | H96: - DailyPrecipitation | J96: - DailyPrecipitation | L96: - DailyPrecipitation | M96: - DailyPrecipitation | Q96: - DailyPrecipitation
A97: - MaxHourlyPrecipitation | C97: - MaxHourlyPrecipitation | F97: - MaxHourlyPrecipitation | H97: - MaxHourlyPrecipitation | J97: - MaxHourlyPrecipitation | L97: - MaxHourlyPrecipitation | M97: - MaxHourlyPrecipitation | Q97: - MaxHourlyPrecipitation
A98: - HDMaxPrecipitation | C98: - HDMaxPrecipitation | F98: - HDMaxPrecipitation | H98: - HDMaxPrecipitation | J98: - HDMaxPrecipitation | L98: - HDMaxPrecipitation | M98: - HDMaxPrecipitation | Q98: - HDMaxPrecipitation
A99: - DailyMeanTemperature | C99: - DailyMeanTemperature | F99: - DailyMeanTemperature | H99: - DailyMeanTemperature | J99: - DailyMeanTemperature | L99: - DailyMeanTemperature | M99: - DailyMeanTemperature | Q99: - DailyMeanTemperature
A100: - HourlyMinTemperature | C100: - HourlyMinTemperature | F100: - HourlyMinTemperature | H100: - HourlyMinTemperature | J100: - HourlyMinTemperature | L100: - HourlyMinTemperature | M100: - HourlyMinTemperature | Q100: - HourlyMinTemperature
A101: - HDMinTemperature | C101: - HDMinTemperature | F101: - HDMinTemperature | H101: - HDMinTemperature | J101: - HDMinTemperature | L101: - HDMinTemperature | M101: - HDMinTemperature | Q101: - HDMinTemperature
A102: - HourlyMaxTemperature | C102: - HourlyMaxTemperature | F102: - HourlyMaxTemperature | H102: - HourlyMaxTemperature | J102: - HourlyMaxTemperature | L102: - HourlyMaxTemperature | M102: - HourlyMaxTemperature | Q102: - HourlyMaxTemperature
A103: - yhat | C103: - yhat | F103: - yhat | H103: - yhat | J103: - yhat | L103: - yhat | M103: - yhat | Q103: - yhat
A104: - weekly | C104: - weekly | F104: - weekly | H104: - weekly | J104: - weekly | L104: - weekly | M104: - weekly | Q104: - weekly
A105: - trend | C105: - trend | F105: - yearly | H105: - yearly | J105: - Month | L105: - yearly | M105: - yearly | Q105: - Month
A106: - yearly | C106: - yearly | F106: - trend | H106: - Month | J106: - Week | L106: - Month | M106: - Month | Q106: - Week
A107: - Week | C107: - Week | F107: - Week | H107: - Week | J107: - yearly | L107: - Week | M107: - Week | Q107: - euro per m3
... A112: - Natural gas US | ($/mmbtu) | C112: - euro per m3.1 | F112: - euro per m3.1 | H112: - euro per m3.1 | J112: - euro per kWh.2 | L112: - Opbouw bbp vanuit de finale bestedingen|Finale bestedingen|Nationale finale bestedingen|Consumptieve bestedingen|Huishoudens | M112: - CPI | 2015 = 100 | Q112: - Opbouw bbp vanuit de finale bestedingen|Finale bestedingen|Nationale finale bestedingen|Bruto investeringen in vaste activa|Overheid
A113: - euro per m3 | L113: - trend | M113: - trend | Q113: - trend
Q114: - yearly

Sheet Both
B1: RMSE | C1: MAPE | D1: PCC | E1: Epoch | F1: Quantum_RMSE | G1: Quantum_MAPE | H1: Quantum_PCC | I1: Quantum_Epoch | J1: Baseline | K1: Stacked_RMSE | L1: Stacked_MAPE | M1: Stacked_PCC
A2: Fold 1 -1440 | B2: 2077.7 | C2: 15.4 | D2: 0.57 | E2: 7 | F2: 2647.09 | G2: 21.45 | H2: 0.445 | I2: 6 | J2: 15.98 | K2: 2001.7 | L2: 14.2 | M2: 0.579
A3: Fold 2-1440 | B3: 1885.6 | C3: 12.64 | D3: 0.554 | E3: 7 | F3: 2006.7 | G3: 12.47 | H3: 0.641 | I3: 18 | J3: 17.72 | K3: 1841.61 | L3: 11.75 | M3: 0.642
A4: Fold 3-1440 | B4: 2043.19 | C4: 20.6 | D4: 0.709 | E4: 9 | F4: 2348.55 | G4: 19.89 | H4: 0.695 | I4: 9 | J4: 15.47 | K4: 1673.53 | L4: 10.33 | M4: 0.695
A5: Fold 4-1440 | B5: 2207.33 | C5: 19.72 | D5: 0.621 | E5: 6 | F5: 2301.46 | G5: 18.03 | H5: 0.563 | I5: 10 | J5: 13.28 | K5: 1728.78 | L5: 10.89 | M5: 0.572
A6: Fold 5-1440 | B6: 2613.62 | C6: 15.95 | D6: 0.471 | E6: 9 | F6: 1904.36 | G6: 14.58 | H6: 0.555 | I6: 6 | J6: 15.55 | K6: 1912.17 | L6: 11.87 | M6: 0.564
A7: Fold 6-1440 | B7: 2355.41 | C7: 17.46 | D7: 0.524 | E7: 8 | F7: 3040.63 | G7: 26.75 | H7: 0.367 | I7: 6 | J7: 14.37 | K7: 1905.51 | L7: 11.91 | M7: 0.544
A8: Fold 7-1440 | B8: 1702.52 | C8: 9.9 | D8: 0.606 | E8: 7 | F8: 1983.63 | G8: 14.54 | H8: 0.45 | I8: 10 | J8: 0.1425 | K8: 1887.02 | L8: 11.69 | M8: 0.45
A9: Fold 8-1440 | B9: 2651.86 | C9: 17.15 | D9: 0.219 | E9: 7 | F9: 3007.05 | G9: 18.54 | H9: 0.257 | I9: 10 | J9: 0.1425 | K9: 1847.41 | L9: 12.09 | M9: 0.646
A10: Fold 1-770 | B10: 2216.79 | C10: 18.76 | D10: 0.307 | E10: 7 | F10: 2330.79 | G10: 16.7 | H10: 0.527 | I10: 7 | J10: 17.65 | K10: 1961.48 | L10: 12.81 | M10: 0.586
A11: Fold 2-770 | B11: 2562.1 | C11: 20.08 | D11: 0.425 | E11: 7 | F11: 2303.72 | G11: 22.95 | H11: 0.454 | I11: 6 | J11: 17.12 | K11: 1900.4869 | L11: 11.882222 | M11: 0.54661111
A12: Fold 3-770 | B12: 1909.64 | C12: 12.79 | D12: 0.636 | E12: 7 | F12: 2059.33 | G12: 15.74 | H12: 0.507 | I12: 6 | J12: 16.81 | K12: 1723.38 | L12: 10.89 | M12: 0.564
A13: Fold 4-770 | B13: 2174.97 | C13: 18.77 | D13: 0.548 | E13: 7 | F13: 2544.95 | G13: 18.74 | H13: 0.449 | I13: 12 | J13: 12.59 | K13: 2100.61 | L13: 13.78 | M13: 0.411
... A17: Fold 8-770 | B17: 2532.29 | C17: 17.48 | D17: 0.23 | E17: 8 | F17: 2291.95 | G17: 19.79 | H17: 0.24 | I17: 6 | J17: 12.59 | K17: 1872.74 | L17: 11.749 | M17: 0.3315
A18: avg | B18: =GEOMEAN(B2:B17) -> 2218.2339 | C18: =GEOMEAN(C2:C17) -> 16.399728 | D18: =GEOMEAN(D2:D17) -> 0.44166545 | E18: =GEOMEAN(E2:E17) -> 7.8769582 | F18: =GEOMEAN(F2:F17) -> 2367.686 | G18: =GEOMEAN(G2:G17) -> 18.502185 | H18: =GEOMEAN(H2:H17) -> 0.43324272 | I18: =GEOMEAN(I2:I17) -> 7.6484287 | ... M18: =GEOMEAN(M2:M17) -> 0.51104978
A20: RMSE T-test | B20: =_xlfn.T.TEST(B2:B17,F2:F17,1,1) -> 0.050236278
A21: MAPE T.test | B21: =_xlfn.T.TEST(C2:C17,G2:G17,1,1) -> 0.029845999
A22: PCC T-test | B22: =_xlfn.T.TEST(D2:D17,H2:H17,1,1) -> 0.23414764
A23: EPOCH T-test | B23: =_xlfn.T.TEST(E2:E17,I2:I17,1,1) -> 0.42042599
A25: RMSE T-test | B25: =_xlfn.T.TEST(B2:B17,K2:K17,1,1) -> 0.00012662942
A26: MAPE T.test | B26: =_xlfn.T.TEST(C2:C17,L2:L17,1,1) -> 1.9894105e-05
A27: PCC T-test | B27: =_xlfn.T.TEST(D2:D17,L2:L17,1,1) -> 2.9974544e-17

Sheet Till2024
B1: RMSE | C1: MAPE | D1: PCC | E1: Epoch | F1: Quantum_RMSE | G1: Quantum_MAPE | H1: Quantum_PCC | I1: Quantum_Epoch | J1: Baseline | K1: Stacked_RMSE | L1: Stacked_MAPE | M1: Stacked_PCC
A2: Fold 1 - 770 | B2: 1990.54 | C2: 12.61 | D2: 0.096 | E2: 4 | F2: 2002.19 | G2: 16.89 | H2: -0.249 | I2: 4 | J2: 13.18 | K2: 1733.13 | L2: 11.89 | M2: 0.293
A3: Fold 2 - 770 | B3: 2451.51 | C3: 21.88 | D3: 0.025 | E3: 3 | F3: 2655.76 | G3: 23.39 | H3: -0.141 | I3: 3 | J3: 14.53 | K3: 1903.48 | L3: 13.95 | M3: 0.143
A4: Fold 3 - 770 | B4: 1894.26 | C4: 16.15 | D4: 0.301 | E4: 3 | F4: 1867.89 | G4: 12.06 | H4: 0.219 | I4: 3 | J4: 15.76 | K4: 1871.06 | L4: 11.77 | M4: 0.3
A5: Fold 4 - 770 | B5: 3466.72 | C5: 28.12 | D5: 0.277 | E5: 3 | F5: 2315.73 | G5: 22.65 | H5: 0.244 | I5: 3 | J5: 11.57 | K5: 1810.98 | L5: 11.19 | M5: 0.25
A6: Fold 1 - 770 | B6: 1948.45 | C6: 12.87 | D6: -0.022 | E6: 6 | F6: 2839.04 | G6: 21.33 | H6: 0.138 | I6: 3 | J6: 13.18 | K6: 1707.07 | L6: 11.49 | M6: 0.336
A7: Fold 2 - 770 | B7: 2428.6 | C7: 21.24 | D7: 0.04 | E7: 3 | F7: 2328.96 | G7: 17.72 | H7: 0.037 | I7: 3 | J7: 14.53 | K7: 1868.36 | L7: 13.22 | M7: 0.237
A8: Fold 3 - 770 | B8: 1884.91 | C8: 19.42 | D8: 0.301 | E8: 3 | F8: 1948.12 | G8: 12.36 | H8: 0.041 | I8: 3 | J8: 15.76 | K8: 1958.74 | L8: 12.53 | M8: 0.054
A9: Fold 4 - 770 | B9: 2958.77 | C9: 23.01 | D9: 0.245 | E9: 3 | F9: 2576.46 | G9: 27.44 | H9: 0.099 | I9: 3 | J9: 11.57 | K9: 1834.62 | L9: 11.59 | M9: 0.195
A10: Fold 1 - 770 | B10: 1902.94 | C10: 15.62 | D10: -0.034 | E10: 7 | F10: 2024.85 | G10: 15.8 | H10: -0.144 | I10: 4 | J10: 13.18 | K10: 1783.96 | L10: 12.24 | M10: 0.177
A11: Fold 2 - 770 | B11: 2637.6 | C11: 22.38 | D11: 0.009 | E11: 3 | F11: 2400.01 | G11: 21.14 | H11: -0.04 | I11: 3 | J11: 14.53 | K11: 1904.82 | L11: 13.71 | M11: 0.138
A12: Fold 3 - 770 | B12: 1947.66 | C12: 18.42 | D12: 0.301 | E12: 3 | F12: 1982.25 | G12: 12.45 | H12: -0.013 | I12: 3 | J12: 15.76 | K12: 1960.67 | L12: 12.73 | M12: 0.03
A13: Fold 4 - 770 | B13: 3056.46 | C13: 28.67 | D13: 0.24 | E13: 3 | F13: 2258.16 | G13: 22.76 | H13: 0.154 | I13: 3 | J13: 11.57 | K13: 1832.74 | L13: 11.49 | M13: 0.2
... A17: Fold 4 - 770 | B17: 2627.92 | C17: 21.84 | D17: 0.221 | E17: 3 | F17: 2394.19 | G17: 25.51 | H17: 0.189 | I17: 3 | J17: 11.57 | K17: 1827.58 | L17: 11.39 | M17: 0.213
A18: Average | B18: =GEOMEAN(B2:B17) -> 2321.1052 | C18: =GEOMEAN(C2:C17) -> 19.053355 | D18: =SUM(D2:D17)/16 -> 0.1539375 | E18: =GEOMEAN(E2:E17) -> 3.4241401 | F18: =GEOMEAN(F2:F17) -> 2265.821 | G18: =GEOMEAN(G2:G17) -> 18.911993 | H18: =SUM(H2:H17)/16 -> 0.043875 | I18: =GEOMEAN(I2:I17) -> 3.1662651 | J18: =GEOMEAN(J2:J17) -> 13.669973 | K18: =GEOMEAN(K2:K17) -> 1841.7189 | L18: =GEOMEAN(L2:L17) -> 12.232205 | M18: =GEOMEAN(M2:M17) -> 0.17715738
A19: Standard deviation | B19: =STDEV(B2:B18) -> 481.29682 | C19: =STDEV(C2:C18) -> 4.6507627 | D19: =STDEV(D2:D18) -> 0.14911592 | E19: =STDEV(E2:E18) -> 1.1714179 | F19: =STDEV(F2:F18) -> 297.47102 | G19: =STDEV(G2:G18) -> 5.4486208 | H19: =STDEV(H2:H18) -> 0.14271163 | I19: =STDEV(I2:I18) -> 0.39034635 | ... M19: =STDEV(M2:M18) -> 0.090989511
A20: T test RMSE | B20: =_xlfn.T.TEST(B2:B17,F2:F17,1,1) -> 0.23902212 | C20: LSTM vs QLSTM | O20: Stacked_RMSE | P20: Stacked_MAPE | Q20: Stacked_PCC
A21: T test mape | B21: =_xlfn.T.TEST(C2:C17,G2:G17,1,1) -> 0.4737478 | N21: Fold 1 | O21: 1738.41 | P21: 12.17 | Q21: 0.259
A22: T test PCC | B22: =_xlfn.T.TEST(B4:B19,F4:F19,1,1) -> 0.16751481 | N22: Fold 2 | O22: 1884.18 | P22: 13.99 | Q22: 0.155
A23: T-Test Epoch | B23: =_xlfn.T.TEST(E2:E17,I2:I17,1,1) -> 0.094068531 | N23: Fold 3 | O23: 1748.79 | P23: 10.87 | Q23: 0.661
N24: Fold 4 | O24: 1654.85 | P24: 10.13 | Q24: 0.435
A25: T test RMSE | B25: =_xlfn.T.TEST(B2:B17,K2:K17,1,1) -> 0.00042074216 | C25: LSTM vs Stacked | N25: Fold 1 | O25: 1772.73 | P25: 12.18 | Q25: 0.172
A26: T test mape | B26: =_xlfn.T.TEST(C2:C17,L2:L17,1,1) -> 1.0737451e-05 | N26: Fold 2 | O26: 1866.42 | P26: 13.94 | Q26: 0.206
A27: T test PCC | B27: =_xlfn.T.TEST(D2:D17,M2:M17,1,1) -> 0.15440982 | N27: Fold 3 | O27: 1705.34 | P27: 10.92 | Q27: 0.514
N28: Fold 4 | O28: 1668.80 | P28: 10.57 | Q28: 0.419
N29: Fold 1 | O29: 1721.66 | P29: 11.97 | Q29: 0.291
N30: Fold 2 | O30: 1868.86 | P30: 13.95 | Q30: 0.199
N31: Fold 3 | O31: 1875.95 | P31: 11.83 | Q31: 0.331
N32: Fold 4 | O32: 1675.73 | P32: 10.38 | Q32: 0.411
B33: RMSE | C33: MAPE | D33: PCC | E33: Epoch | F33: Quantum_RMSE | G33: Quantum_MAPE | H33: Quantum_PCC | I33: Quantum_Epoch | J33: Baseline | K33: Stacked_RMSE | L33: Stacked_MAPE | M33: Stacked_PCC
A34: Fold 1 | B34: 4495.80 | C34: 55.25 | D34: 0.424 | E34: 3 | F34: 2297.82 | G34: 16.88 | H34: -0.126 | I34: 3 | J34: 12.98 | K34: 1738.41 | L34: 12.17 | M34: 0.259
A35: Fold 2 | B35: 2456.48 | C35: 19.56 | D35: -0.108 | E35: 3 | F35: 2449.28 | G35: 22.31 | H35: -0.143 | I35: 3 | J35: 15.30 | K35: 1884.18 | L35: 13.99 | M35: 0.155
A36: Fold 3 | B36: 2768.40 | C36: 18.86 | D36: 0.714 | E36: 8 | F36: 2270.54 | G36: 17.57 | H36: 0.658 | I36: 12 | J36: 15.51 | K36: 1748.79 | L36: 10.87 | M36: 0.661
A37: Fold 4 | B37: 2088.23 | C37: 13.73 | D37: 0.347 | E37: 8 | F37: 1936.80 | G37: 13.08 | H37: 0.363 | I37: 11 | J37: 11.44 | K37: 1654.85 | L37: 10.13 | M37: 0.435
A38: Fold 1 | B38: 3864.58 | C38: 33.50 | D38: 0.388 | F38: 1944.03 | G38: 16.62 | H38: 0.036 | I38: 9 | J38: 12.98 | K38: 1772.73 | L38: 12.18 | M38: 0.172
A39: Fold 2 | B39: 2075.81 | C39: 15.11 | D39: 0.222 | E39: 25 | F39: 2415.80 | G39: 24.34 | H39: 0.179 | I39: 6 | J39: 15.30 | K39: 1866.42 | L39: 13.94 | M39: 0.206
A40: Fold 3 | B40: 1788.71 | C40: 10.89 | D40: 0.446 | E40: 6 | F40: 1904.48 | G40: 11.17 | H40: 0.376 | I40: 10 | J40: 14.25 | K40: 1705.34 | L40: 10.92 | M40: 0.514
A41: Fold 4 | B41: 2131.33 | C41: 17.19 | D41: 0.328 | E41: 6 | F41: 2218.26 | G41: 17.28 | H41: 0.035 | I41: 6 | J41: 11.44 | K41: 1668.80 | L41: 10.57 | M41: 0.419
A42: Fold 1 | B42: 4685.54 | C42: 57.64 | D42: 0.405 | E42: 6 | F42: 2414.28 | G42: 24.64 | H42: 0.253 | I42: 6 | J42: 12.98 | K42: 1721.66 | L42: 11.97 | M42: 0.291
A43: Fold 2 | B43: 2242.24 | C43: 20.30 | D43: 0.001 | E43: 6 | F43: 2295.09 | G43: 25.34 | H43: 0.171 | I43: 8 | J43: 15.30 | K43: 1868.86 | L43: 13.95 | M43: 0.199
...

Sheet Sheet6
B1: 770 - 8folds | C1: 1440 -8 folds | D1: 770-4folds | E1: 1440-4folds
A2: RMSE T-Test
A3: MAPE T-test
A4: PCC T-test

Sheet Sheet5
B1: RMSE | C1: MAPE | D1: PCC | E1: Epoch | F1: Quantum_RMSE | G1: Quantum_MAPE | H1: Quantum_PCC | I1: Quantum_Epoch | J1: Baseline | K1: Stacked_RMSE | L1: Stacked_MAPE | M1: Stacked_PCC
A2: Fold 1 | B2: 4495.8 | C2: 55.25 | D2: 0.424 | E2: 3 | F2: 2297.82 | G2: 16.88 | H2: -0.126 | I2: 3 | J2: 12.98 | K2: 1738.41 | L2: 12.17 | M2: 0.259
A3: Fold 2 | B3: 2456.48 | C3: 19.56 | D3: -0.108 | E3: 3 | F3: 2449.28 | G3: 22.31 | H3: -0.143 | I3: 3 | J3: 15.3 | K3: 1884.18 | L3: 13.99 | M3: 0.155
A4: Fold 3 | B4: 2768.4 | C4: 18.86 | D4: 0.714 | E4: 8 | F4: 2270.54 | G4: 17.57 | H4: 0.658 | I4: 12 | J4: 15.51 | K4: 1748.79 | L4: 10.87 | M4: 0.661
A5: Fold 4 | B5: 2088.23 | C5: 13.73 | D5: 0.347 | E5: 8 | F5: 1936.8 | G5: 13.08 | H5: 0.363 | I5: 11 | J5: 11.44 | K5: 1654.85 | L5: 10.13 | M5: 0.435
A6: Fold 1 | B6: 3864.58 | C6: 33.5 | D6: 0.388 | F6: 1944.03 | G6: 16.62 | H6: 0.036 | I6: 9 | J6: 12.98 | K6: 1772.73 | L6: 12.18 | M6: 0.172
A7: Fold 2 | B7: 2075.81 | C7: 15.11 | D7: 0.222 | E7: 25 | F7: 2415.8 | G7: 24.34 | H7: 0.179 | I7: 6 | J7: 15.3 | K7: 1866.42 | L7: 13.94 | M7: 0.206
A8: Fold 3 | B8: 1788.71 | C8: 10.89 | D8: 0.446 | E8: 6 | F8: 1904.48 | G8: 11.17 | H8: 0.376 | I8: 10 | J8: 14.25 | K8: 1705.34 | L8: 10.92 | M8: 0.514
A9: Fold 4 | B9: 2131.33 | C9: 17.19 | D9: 0.328 | E9: 6 | F9: 2218.26 | G9: 17.28 | H9: 0.035 | I9: 6 | J9: 11.44 | K9: 1668.8 | L9: 10.57 | M9: 0.419
A10: Fold 1 | B10: 4685.54 | C10: 57.64 | D10: 0.405 | E10: 6 | F10: 2414.28 | G10: 24.64 | H10: 0.253 | I10: 6 | J10: 12.98 | K10: 1721.66 | L10: 11.97 | M10: 0.291
A11: Fold 2 | B11: 2242.24 | C11: 20.3 | D11: 0.001 | E11: 6 | F11: 2295.09 | G11: 25.34 | H11: 0.171 | I11: 8 | J11: 15.3 | K11: 1868.86 | L11: 13.95 | M11: 0.199
A12: Fold 3 | B12: 1975.98 | C12: 11.29 | D12: 0.354 | E12: 6 | F12: 1906.54 | G12: 11.29 | H12: 0.354 | I12: 6 | J12: 14.25 | K12: 1875.95 | L12: 11.83 | M12: 0.331
A13: Fold 4 | B13: 2041.99 | C13: 14.81 | D13: 0.397 | E13: 7 | F13: 1944.74 | G13: 15.39 | H13: 0.267 | I13: 7 | J13: 11.44 | K13: 1675.73 | L13: 10.38 | M13: 0.411
A14: Average | B14: =GEOMEAN(B2:B13) -> 2569.3533 | C14: =GEOMEAN(C2:C13) -> 20.397782 | D14: =SUM(D2:D13)/12 -> 0.3265 | E14: =GEOMEAN(E2:E13) -> 6.4352461 | F14: =GEOMEAN(F2:F13) -> 2156.0128 | G14: =GEOMEAN(G2:G13) -> 17.32866 | H14: =SUM(H2:H13)/12 -> 0.20191667 | I14: =GEOMEAN(I2:I13) -> 6.9101694 | J14: =GEOMEAN(J2:J13) -> 13.508843 | K14: =GEOMEAN(K2:K13) -> 1763.1894 | L14: =GEOMEAN(L2:L13) -> 11.832698 | M14: =GEOMEAN(M2:M13) -> 0.30674388
A15: standard deviation | B15: =STDEV(B2:B13) -> 1029.9195 | C15: =STDEV(C2:C13) -> 16.256572 | D15: =STDEV(D2:D13) -> 0.21228133 | E15: =STDEV(E2:E13) -> 5.9878665 | F15: =STDEV(F2:F13) -> 221.24849 | G15: =STDEV(G2:G13) -> 5.0748025 | H15: =STDEV(H2:H13) -> 0.22914999 | I15: =STDEV(I2:I13) -> 3.2403703 | ... M15: =STDEV(M2:M13) -> 0.15459397
A17: Classic vs Quantum
A18: RMSE T,test | B18: =_xlfn.T.TEST(B2:B13,F2:F13,1,1) -> 0.03793417
A19: Mape T.test | B19: =_xlfn.T.TEST(C2:C13,G2:G13,1,1) -> 0.098383043
A20: Pcc | B20: =_xlfn.T.TEST(D2:D13,H2:H13,1,1) -> 0.023121219
A23: Classic vs stacked
A24: RMSE T,test | B24: =_xlfn.T.TEST(B2:B13,K2:K13,1,1) -> 0.0045110156
A25: Mape T.test | B25: =_xlfn.T.TEST(C2:C13,L2:L13,1,1) -> 0.01226418
A26: Pcc | B26: =_xlfn.T.TEST(D2:D13,M2:M13,1,1) -> 0.39356257

Sheet 1440
B1: RMSE | C1: MAPE | D1: PCC | E1: Epoch | F1: Quantum_RMSE | G1: Quantum_MAPE | H1: Quantum_PCC | I1: Quantum_Epoch | J1: Baseline | K1: Stacked_RMSE | L1: Stacked_MAPE | M1: Stacked_PCC
A2: Fold 1 | B2: 2077.7 | C2: 15.4 | D2: 0.57 | E2: 7 | F2: 2647.09 | G2: 21.45 | H2: 0.445 | I2: 6 | J2: 15.98 | K2: 2001.7 | L2: 14.2 | M2: 0.579
A3: Fold 2 | B3: 1885.6 | C3: 12.64 | D3: 0.554 | E3: 7 | F3: 2006.7 | G3: 12.47 | H3: 0.641 | I3: 18 | J3: 17.72 | K3: 1841.61 | L3: 11.75 | M3: 0.642
A4: Fold 3 | B4: 2043.19 | C4: 20.6 | D4: 0.709 | E4: 9 | F4: 2348.55 | G4: 19.89 | H4: 0.695 | I4: 9 | J4: 15.47 | K4: 1673.53 | L4: 10.33 | M4: 0.695
A5: Fold 4 | B5: 2207.33 | C5: 19.72 | D5: 0.621 | E5: 6 | F5: 2301.46 | G5: 18.03 | H5: 0.563 | I5: 10 | J5: 13.28 | K5: 1728.78 | L5: 10.89 | M5: 0.572
A6: Fold 5 | B6: 2613.62 | C6: 15.95 | D6: 0.471 | E6: 9 | F6: 1904.36 | G6: 14.58 | H6: 0.555 | I6: 6 | J6: 15.55 | K6: 1912.17 | L6: 11.87 | M6: 0.564
A7: Fold 6 | B7: 2355.41 | C7: 17.46 | D7: 0.524 | E7: 25 | F7: 3040.63 | G7: 26.75 | H7: 0.367 | I7: 6 | J7: 14.37 | K7: 1905.51 | L7: 11.91 | M7: 0.544
A8: Fold 7 | B8: 1702.52 | C8: 9.9 | D8: 0.606 | E8: 7 | F8: 1983.63 | G8: 14.54 | H8: 0.45 | I8: 10 | J8: 0.1425 | K8: 1887.02 | L8: 11.69 | M8: 0.45
A9: Fold 8 | B9: 2651.86 | C9: 17.15 | D9: 0.219 | E9: 7 | F9: 3007.05 | G9: 18.54 | H9: 0.257 | I9: 10 | J9: 14.25 | K9: 1847.41 | L9: 12.09 | M9: 0.646
A10: Average | B10: =GEOMEAN(B2:B9) -> 2169.6767 | C10: =GEOMEAN(C2:C9) -> 15.725095 | D10: =GEOMEAN(D2:D9) -> 0.50968156 | E10: =GEOMEAN(E2:E9) -> 8.5727677 | F10: =GEOMEAN(F2:F9) -> 2368.8963 | G10: =GEOMEAN(G2:G9) -> 17.801638 | H10: =GEOMEAN(H2:H9) -> 0.47585758 | I10: =GEOMEAN(I2:I9) -> 8.7699294 | ... M10: =GEOMEAN(M2:M9) -> 0.58208939
B11: =STDEV(B2:B10) -> 313.30933 | C11: =STDEV(C2:C10) -> 3.3044886 | D11: =STDEV(D2:D10) -> 0.13642949 | E11: =STDEV(E2:E10) -> 5.9040153 | F11: =STDEV(F2:F10) -> 422.34387 | G11: =STDEV(G2:G10) -> 4.2741981 | H11: =STDEV(H2:H10) -> 0.13576415 | I11: =STDEV(I2:I10) -> 3.711476 | ... M11: =STDEV(M2:M10) -> 0.070375148
A16: - DailyPrecipitation | B16: - DailyPrecipitation | E16: - DailyPrecipitation | H16: - DailyPrecipitation | N16: - DailyPrecipitation
A17: - MaxHourlyPrecipitation | B17: - MaxHourlyPrecipitation | E17: - MaxHourlyPrecipitation | H17: - MaxHourlyPrecipitation | N17: - MaxHourlyPrecipitation
A18: - HDMaxPrecipitation | B18: - HDMaxPrecipitation | E18: - HDMaxPrecipitation | H18: - HDMaxPrecipitation | N18: - HDMaxPrecipitation
A19: - DailyMeanTemperature | B19: - DailyMeanTemperature | E19: - DailyMeanTemperature | H19: - DailyMeanTemperature | N19: - DailyMeanTemperature
A20: - HourlyMinTemperature | B20: - HourlyMinTemperature | E20: - HourlyMinTemperature | H20: - HourlyMinTemperature | N20: - HourlyMinTemperature
A21: - HDMinTemperature | B21: - HDMinTemperature | E21: - HDMinTemperature | H21: - HDMinTemperature | N21: - HDMinTemperature
A22: - HourlyMaxTemperature | B22: - HourlyMaxTemperature | E22: - HourlyMaxTemperature | H22: - HourlyMaxTemperature | N22: - HourlyMaxTemperature
A23: - yhat | B23: - yhat | E23: - yhat | H23: - yhat | N23: - yhat
A24: - weekly | B24: - weekly | E24: - weekly | H24: - weekly | N24: - weekly
A25: - trend | B25: - trend | E25: - yearly | H25: - trend | N25: - Month
A26: - euro per m3,1 | B26: - yearly | E26: - trend | H26: - Month | N26: - Week
A27: - euro per kWh,1 | B27: - Month | E27: - Month | H27: - Week | N27: - euro per m3
... A30: - Month | B30: - euro per m3 | E30: - euro per kWh,2 | H30: - euro per kWh,1 | N30: - Opbouw bbp vanuit de finale bestedingen|Finale bestedingen|Nationale finale bestedingen|Verandering in voorraden
A31: - Week | B31: - euro per kWh,1 | E31: - Coal | F31: Australian | ($/mt) | H31: - euro per kWh,2 | N31: - CPI afgeleid | 2015 = 100
A32: - euro per kWh,2 | B32: - Crude oil | C32: WTI | ($/bbl) | E32: - euro per kWh,1 | H32: - Coal | I32: Australian | ($/mt) | N32: - CPI | 2015 = 100
N33: - trend
A40: - DailyPrecipitation | E40: - DailyPrecipitation
A41: - MaxHourlyPrecipitation | E41: - MaxHourlyPrecipitation
A42: - HDMaxPrecipitation | E42: - HDMaxPrecipitation
A43: - DailyMeanTemperature | E43: - DailyMeanTemperature
A44: - HourlyMinTemperature | E44: - HourlyMinTemperature
A45: - HDMinTemperature | E45: - HDMinTemperature
A46: - HourlyMaxTemperature | E46: - HourlyMaxTemperature
A47: - yhat | E47: - yhat
A48: - weekly | E48: - weekly
A49: - trend | E49: - Month
A50: - Month | E50: - Week
A51: - Week | E51: - yearly
... A54: - Electriciy Price | E54: - euro per kWh,1
...
